Workbook

Sheet Assumptions
B2: Prior Authorization Modernization — Cost Model
B3: Assumptions
B4: Prepared for Richard Williams, IBM • July 2026
B5: All figures below are illustrative planning-level placeholders (not quotes) — cells in blue are inputs. Replace with actual rates/quotes when known.
B7: Labor Rates ($ / day, blended)
B8: Role | C8: Daily Rate ($) | E8: Note
B9: Tech Lead | C9: 1450 | E9: Illustrative U.S. blended consulting rate — replace with actual rate
B10: Backend/FHIR Engineer 1 | C10: 1100 | E10: Illustrative U.S. blended consulting rate — replace with actual rate
B11: Backend/FHIR Engineer 2 | C11: 1100 | E11: Illustrative U.S. blended consulting rate — replace with actual rate
B12: Data/Integration Engineer | C12: 1100 | E12: Illustrative U.S. blended consulting rate — replace with actual rate
B13: Frontend Engineer | C13: 1000 | E13: Illustrative U.S. blended consulting rate — replace with actual rate
B14: QA Engineer | C14: 900 | E14: Illustrative U.S. blended consulting rate — replace with actual rate
B15: Security Engineer | C15: 1250 | E15: Illustrative U.S. blended consulting rate — replace with actual rate
B16: Product/Clinical SME | C16: 1300 | E16: Illustrative U.S. blended consulting rate — replace with actual rate
B17: Project Manager | C17: 1050 | E17: Illustrative U.S. blended consulting rate — replace with actual rate
B18: Clinical Policy Reviewer | C18: 950 | E18: Illustrative U.S. blended consulting rate — replace with actual rate
B20: Schedule Assumptions
B21: Working days per week | C21: 5 | E21: Standard 5-day work week
B22: Build duration (weeks) | C22: 18 | E22: From the Implementation Plan — total project End Week
B23: Avg. working days per month | C23: 21.7 | E23: 52 weeks x 5 days / 12 months
B24: Build duration (months) | C24: =C22*C21/C23 -> 4.1474654 | E24: Calculated from build duration in weeks
B26: Cloud Hosting — Infrastructure (Monthly, USD)
B27: Cloud Provider | C27: Azure | E27: Select AWS or Azure — drives the Total Infrastructure cost below. Default set to Azure per the Idaho Medicaid CMS-0057 assessment (Infrastructure Q1: Azure preferred for state projects)
B28: Component | C28: AWS ($/mo) | D28: Azure ($/mo) | E28: Note
B29: Compute — CRD/DTR/PAS microservices | C29: 1400 | D29: 1500 | E29: AWS Fargate (ECS) / Azure Container Apps
B30: Managed FHIR Datastore | C30: 2800 | D30: 3200 | E30: AWS HealthLake / Azure Health Data Services (FHIR service)
B31: PA Aggregation DB & Object Storage | C31: 600 | D31: 650 | E31: RDS Postgres + S3 / Azure Cosmos DB + Blob Storage
B32: DTR SMART App Hosting (CDN) | C32: 300 | D32: 300 | E32: CloudFront + S3 / Azure Static Web Apps + CDN
B33: API Gateway / Load Balancer | C33: 250 | D33: 280 | E33: AWS ALB + API Gateway / Azure API Management
B34: Backup & Disaster Recovery | C34: 400 | D34: 450 | E34: Cross-region backup and point-in-time recovery
B35: Monitoring & Logging | C35: 300 | D35: 320 | E35: Amazon CloudWatch / Azure Monitor
B36: Security — WAF, Key Mgmt, Secrets | C36: 250 | D36: 270 | E36: AWS WAF + KMS / Azure Front Door WAF + Key Vault
B37: Total Infrastructure (Monthly, Selected Provider) | C37: =IF(C27="AWS",SUM(C29:C36),SUM(D29:D36)) -> 6970
B39: Integration Scope — EMR Connections
B40: EMR connections included in base build | C40: 1 | E40: Base build (Phase 4b) integrates one EMR via generic US Core v3
B41: Total EMR connections in scope | C41: 4 | E41: Idaho: Epic + Oracle Health/Cerner + MEDITECH + 1 platform for remaining independent/CAH facilities — see Idaho EMR & Facility Landscape below
B42: Cost per additional EMR connection (one-time) | C42: 35000 | E42: Vendor app-store certification (e.g., Epic App Orchard), sandbox integration & testing
B43: Cost per additional EMR connection (monthly, ongoing) | C43: 500 | E43: Ongoing vendor fees + maintenance per connected EMR
B44: Additional EMR connections | C44: =MAX(0,C41-C40) -> 3 | E44: Total minus what the base build already includes
B46: Idaho EMR & Facility Landscape
...

Sheet Task Cost Detail
A1: ID | B1: Phase | C1: Task | D1: Owner Role | E1: Person-Days | F1: Daily Rate ($) | G1: Task Cost ($)
A2: S0-01 | B2: S0 | C2: Repo & Environment Review | D2: Tech Lead | E2: 3 | F2: =INDEX(Assumptions!$C$9:$C$18,MATCH(D2,Assumptions!$B$9:$B$18,0)) -> 1450 | G2: =E2*F2 -> 4350
A3: S0-02 | B3: S0 | C3: Cut feature/phase4-crd-dtr-pas-integration Branch | D3: Tech Lead | E3: 0.5 | F3: =INDEX(Assumptions!$C$9:$C$18,MATCH(D3,Assumptions!$B$9:$B$18,0)) -> 1450 | G3: =E3*F3 -> 725
A4: S0-03 | B4: S0 | C4: Intelligent Policy Engine Schema Spike | D4: Data/Integration Engineer | E4: 5 | F4: =INDEX(Assumptions!$C$9:$C$18,MATCH(D4,Assumptions!$B$9:$B$18,0)) -> 1100 | G4: =E4*F4 -> 5500
A5: S0-04 | B5: S0 | C5: Milliman/InterQual API Access & Licensing Confirmation | D5: Product/Clinical SME | E5: 3 | F5: =INDEX(Assumptions!$C$9:$C$18,MATCH(D5,Assumptions!$B$9:$B$18,0)) -> 1300 | G5: =E5*F5 -> 3900
A6: S0-05 | B6: S0 | C6: Payer Endpoint Directory & Capability Schema | D6: Backend/FHIR Engineer 1 | E6: 3 | F6: =INDEX(Assumptions!$C$9:$C$18,MATCH(D6,Assumptions!$B$9:$B$18,0)) -> 1100 | G6: =E6*F6 -> 3300
A7: S0-06 | B7: S0 | C7: CI/CD & Environment Setup | D7: Tech Lead | E7: 2 | F7: =INDEX(Assumptions!$C$9:$C$18,MATCH(D7,Assumptions!$B$9:$B$18,0)) -> 1450 | G7: =E7*F7 -> 2900
A8: S0-07 | B8: S0 | C8: Confidence-Threshold Policy Workshop | D8: Product/Clinical SME | E8: 2 | F8: =INDEX(Assumptions!$C$9:$C$18,MATCH(D8,Assumptions!$B$9:$B$18,0)) -> 1300 | G8: =E8*F8 -> 2600
A9: 4A-01 | B9: 4A | C9: CDS Hooks Client | D9: Backend/FHIR Engineer 1 | E9: 5 | F9: =INDEX(Assumptions!$C$9:$C$18,MATCH(D9,Assumptions!$B$9:$B$18,0)) -> 1100 | G9: =E9*F9 -> 5500
A10: 4A-02 | B10: 4A | C10: Prior Auth Service Orchestrator (Skeleton) | D10: Backend/FHIR Engineer 1 | E10: 5 | F10: =INDEX(Assumptions!$C$9:$C$18,MATCH(D10,Assumptions!$B$9:$B$18,0)) -> 1100 | G10: =E10*F10 -> 5500
A11: 4A-03 | B11: 4A | C11: Eligibility & Enrollment Check | D11: Backend/FHIR Engineer 2 | E11: 4 | F11: =INDEX(Assumptions!$C$9:$C$18,MATCH(D11,Assumptions!$B$9:$B$18,0)) -> 1100 | G11: =E11*F11 -> 4400
A12: 4A-04 | B12: 4A | C12: Provider Network Status Check | D12: Backend/FHIR Engineer 2 | E12: 4 | F12: =INDEX(Assumptions!$C$9:$C$18,MATCH(D12,Assumptions!$B$9:$B$18,0)) -> 1100 | G12: =E12*F12 -> 4400
A13: 4A-05 | B13: 4A | C13: Milliman/InterQual Guideline Check | D13: Backend/FHIR Engineer 2 | E13: 4 | F13: =INDEX(Assumptions!$C$9:$C$18,MATCH(D13,Assumptions!$B$9:$B$18,0)) -> 1100 | G13: =E13*F13 -> 4400
... A58: HD-07 | B58: HD | C58: Documentation & Handoff | D58: Tech Lead | E58: 2 | F58: =INDEX(Assumptions!$C$9:$C$18,MATCH(D58,Assumptions!$B$9:$B$18,0)) -> 1450 | G58: =E58*F58 -> 2900
C59: TOTAL | E59: =SUM(E2:E58) -> 204.5 | G59: =SUM(G2:G58) -> 221575

Sheet Cost Summary
B2: Cost Summary — Implementation (Build) Cost
B3: Scope: 1 payer set of test profiles is built/tested in Phase 4b; production EMR and payer connection counts are set in Assumptions.
B5: Labor Cost by Role
B6: Role | C6: Person-Days | D6: Cost ($)
B7: Tech Lead | C7: =SUMIF('Task Cost Detail'!$D$2:$D$1000,B7,'Task Cost Detail'!$E$2:$E$1000) -> 7.5 | D7: =SUMIF('Task Cost Detail'!$D$2:$D$1000,B7,'Task Cost Detail'!$G$2:$G$1000) -> 10875
B8: Backend/FHIR Engineer 1 | C8: =SUMIF('Task Cost Detail'!$D$2:$D$1000,B8,'Task Cost Detail'!$E$2:$E$1000) -> 57 | D8: =SUMIF('Task Cost Detail'!$D$2:$D$1000,B8,'Task Cost Detail'!$G$2:$G$1000) -> 62700
B9: Backend/FHIR Engineer 2 | C9: =SUMIF('Task Cost Detail'!$D$2:$D$1000,B9,'Task Cost Detail'!$E$2:$E$1000) -> 47 | D9: =SUMIF('Task Cost Detail'!$D$2:$D$1000,B9,'Task Cost Detail'!$G$2:$G$1000) -> 51700
B10: Data/Integration Engineer | C10: =SUMIF('Task Cost Detail'!$D$2:$D$1000,B10,'Task Cost Detail'!$E$2:$E$1000) -> 13 | D10: =SUMIF('Task Cost Detail'!$D$2:$D$1000,B10,'Task Cost Detail'!$G$2:$G$1000) -> 14300
B11: Frontend Engineer | C11: =SUMIF('Task Cost Detail'!$D$2:$D$1000,B11,'Task Cost Detail'!$E$2:$E$1000) -> 32 | D11: =SUMIF('Task Cost Detail'!$D$2:$D$1000,B11,'Task Cost Detail'!$G$2:$G$1000) -> 32000
B12: QA Engineer | C12: =SUMIF('Task Cost Detail'!$D$2:$D$1000,B12,'Task Cost Detail'!$E$2:$E$1000) -> 28 | D12: =SUMIF('Task Cost Detail'!$D$2:$D$1000,B12,'Task Cost Detail'!$G$2:$G$1000) -> 25200
B13: Security Engineer | C13: =SUMIF('Task Cost Detail'!$D$2:$D$1000,B13,'Task Cost Detail'!$E$2:$E$1000) -> 4 | D13: =SUMIF('Task Cost Detail'!$D$2:$D$1000,B13,'Task Cost Detail'!$G$2:$G$1000) -> 5000
B14: Product/Clinical SME | C14: =SUMIF('Task Cost Detail'!$D$2:$D$1000,B14,'Task Cost Detail'!$E$2:$E$1000) -> 12 | D14: =SUMIF('Task Cost Detail'!$D$2:$D$1000,B14,'Task Cost Detail'!$G$2:$G$1000) -> 15600
B15: Project Manager | C15: =SUMIF('Task Cost Detail'!$D$2:$D$1000,B15,'Task Cost Detail'!$E$2:$E$1000) -> 4 | D15: =SUMIF('Task Cost Detail'!$D$2:$D$1000,B15,'Task Cost Detail'!$G$2:$G$1000) -> 4200
B16: Clinical Policy Reviewer | C16: =SUMIF('Task Cost Detail'!$D$2:$D$1000,B16,'Task Cost Detail'!$E$2:$E$1000) -> 0 | D16: =SUMIF('Task Cost Detail'!$D$2:$D$1000,B16,'Task Cost Detail'!$G$2:$G$1000) -> 0
B17: Total Labor Cost | C17: =SUM(C7:C16) -> 204.5 | D17: =SUM(D7:D16) -> 221575
B19: Labor Cost by Phase
B20: Phase | C20: Phase Name | D20: Cost ($)
B21: S0 | C21: Sprint 0 — Foundation & Design Spike | D21: =SUMIF('Task Cost Detail'!$B$2:$B$1000,B21,'Task Cost Detail'!$G$2:$G$1000) -> 23275
B22: 4A | C22: Phase 4a — CRD Integration & Checklist UI | D22: =SUMIF('Task Cost Detail'!$B$2:$B$1000,B22,'Task Cost Detail'!$G$2:$G$1000) -> 43750
B23: 4B | C23: Phase 4b — DTR, Aggregation FHIR Server & Necessity Tree UI | D23: =SUMIF('Task Cost Detail'!$B$2:$B$1000,B23,'Task Cost Detail'!$G$2:$G$1000) -> 55150
B24: 4C | C24: Phase 4c — PAS Submission & Channel Routing | D24: =SUMIF('Task Cost Detail'!$B$2:$B$1000,B24,'Task Cost Detail'!$G$2:$G$1000) -> 29300
B25: 4D | C25: Phase 4d — Evidence Record & Status Sync | D25: =SUMIF('Task Cost Detail'!$B$2:$B$1000,B25,'Task Cost Detail'!$G$2:$G$1000) -> 26200
B26: 4E | C26: Phase 4e — Back-Office Batch Worklist | D26: =SUMIF('Task Cost Detail'!$B$2:$B$1000,B26,'Task Cost Detail'!$G$2:$G$1000) -> 17600
B27: HD | C27: Hardening — Integration, Security, Compliance, UAT | D27: =SUMIF('Task Cost Detail'!$B$2:$B$1000,B27,'Task Cost Detail'!$G$2:$G$1000) -> 26300
B29: Scope Detail — EMR, Payer & Other Endpoints
B30: Item | C30: Quantity | D30: Cost ($, one-time)
B31: EMR connections (additional, beyond base build) | C31: =Assumptions!C44 -> 3 | D31: =Assumptions!C44*Assumptions!C42 -> 105000
B32: Payer connections (production onboarding) | C32: =Assumptions!C83 -> 3 | D32: =Assumptions!C83*Assumptions!C84 -> 60000
B33: UM sub-vendor integrations (Magellan/Prime/Internal-style) | C33: =Assumptions!C83*Assumptions!C86 -> 9 | D33: =Assumptions!C83*Assumptions!C86*Assumptions!C87 -> 72000
B34: EDI clearinghouse connection setup | C34: 1 | D34: =Assumptions!C91 -> 8000
B35: Additional HIE / data-source connections | C35: =Assumptions!C92 -> 0 | D35: =Assumptions!C92*Assumptions!C93 -> 0
B36: Idaho facility rollout (per-site install, one-time) | C36: =Assumptions!C55 -> 18 | D36: =Assumptions!C58 -> 72000
B37: Total EMR / Payer / Endpoint Cost | D37: =D31+D32+D33+D34+D35+D36 -> 317000
B39: HIPAA & Compliance Certification
B40: Item | C40: Cost ($, one-time)
B41: HIPAA Risk Assessment & Remediation | C41: =Assumptions!C140 -> 30000
B42: BAA Legal Review & Execution | C42: =Assumptions!C141 -> 5000
B43: SOC 2 Type II — Year 1 (readiness + audit) | C43: =Assumptions!C142 -> 45000
B44: HITRUST CSF Certification (if included) | C44: =IF(Assumptions!C144="Yes",Assumptions!C145,0) -> 0
B45: Total Compliance Cost | C45: =SUM(C41:C44) -> 80000
...

Sheet Ongoing Run-Rate
B2: Ongoing Run-Rate — Post Go-Live (Steady State)
B3: Monthly and annual operating cost once the solution is live, independent of the one-time build cost.
B5: Category | C5: Monthly ($) | D5: Basis
B6: Infrastructure & Hosting (scaled for production) | C6: =Assumptions!C37*Assumptions!C160 -> 8364 | D6: Build-phase infra monthly total (selected cloud provider) x post-launch scale-up factor
B7: Third-Party Licensing (recurring) | C7: =Assumptions!C97/12+Assumptions!C98/12+Assumptions!C99+Assumptions!C101 -> 10500 | D7: Milliman/12 + InterQual/12 + EDI translator + watsonx (post-launch volume)
B8: Backend/FHIR Support Labor | C8: =Assumptions!C158*Assumptions!C10*Assumptions!C23 -> 11935 | D8: Support FTE allocation x daily rate x avg. working days/month
B9: QA Support Labor | C9: =Assumptions!C159*Assumptions!C14*Assumptions!C23 -> 4882.5 | D9: Support FTE allocation x daily rate x avg. working days/month
B10: Additional EMR Connections (maintenance) | C10: =Assumptions!C44*Assumptions!C43 -> 1500 | D10: Additional EMR connections x ongoing monthly rate per connection
B11: Payer Connections (monitoring & fees) | C11: =Assumptions!C83*Assumptions!C85 -> 2250 | D11: Production payer connections x ongoing monthly rate per connection
B12: UM Sub-Vendor Integrations (monitoring & fees) | C12: =Assumptions!C83*Assumptions!C86*Assumptions!C88 -> 2700 | D12: Payer connections x sub-vendors per payer x ongoing monthly rate per sub-vendor
B13: SOC 2 Type II Annual Renewal (amortized monthly) | C13: =Assumptions!C143/12 -> 2083.3333 | D13: Annual renewal cost spread across 12 months
B14: HITRUST CSF Annual Renewal (amortized monthly, if included) | C14: =IF(Assumptions!C144="Yes",Assumptions!C146/12,0) -> 0 | D14: Only non-zero if HITRUST is included in Assumptions
B15: Policy Revision — Clinical Review (amortized monthly) | C15: =Assumptions!C175/12 -> 890.625 | D15: Annual clinical review cost for new/revised payer policies, spread across 12 months
B16: Facility Connectivity (per-install, ongoing) | C16: =Assumptions!C59 -> 2700 | D16: Facilities in scope x monthly cost per facility install (Idaho EMR & Facility Landscape)
B17: Infor Cloverleaf (annual license, amortized monthly, optional) | C17: =IF(Assumptions!C105="Yes",Assumptions!C106/12,0) -> 8333.3333 | D17: Toggle in Assumptions — alternative/complement to the EDI Clearinghouse/Translator line above
B18: CMS-0057-F APIs — Patient/Provider/Payer-to-Payer (ongoing) | C18: =Assumptions!C137 -> 8200 | D18: Patient Access vendor fee + Provider Access hosting + Payer-to-Payer ops + prior payer connection monitoring
B19: Total Monthly Run-Rate | C19: =SUM(C6:C18) -> 64338.792
B20: Total Annual Run-Rate | C20: =C19*12 -> 772065.5
